<?xml version="1.0" ?>
<!-- =================================================================================== -->
<!-- |    This document was autogenerated by xacro from icart_mini.xacro               | -->
<!-- |    EDITING THIS FILE BY HAND IS NOT RECOMMENDED                                 | -->
<!-- =================================================================================== -->
<robot name="icart_mini">
  <link name="base_footprint"/>
  <!-- Base Joint -->
  <joint name="base_joint" type="fixed">
    <origin xyz="0 0 0.126"/>
    <parent link="base_footprint"/>
    <child link="base_link"/>
  </joint>
  <!-- Base Link -->
  <link name="base_link">
    <visual>
      <origin rpy="0 0 0" xyz="0 0 0.25"/>
      <geometry>
        <box size="0.35 0.18 0.4"/>
      </geometry>
      <material name="white">
        <color rgba="1.0 1.0 1.0 1.0"/>
      </material>
    </visual>
    <visual name="back_wheel">
      <origin rpy="0 1.5707 1.5707" xyz="-0.12 0.0 0.05"/>
      <geometry>
        <cylinder length="0.03" radius="0.04625"/>
      </geometry>
      <material name="white">
        <color rgba="1.0 1.0 1.0 1.0"/>
      </material>
    </visual>
    <visual name="front_wheel">
      <origin rpy="0 1.5707 1.5707" xyz="0.12 0.0 0.05"/>
      <geometry>
        <cylinder length="0.03" radius="0.04625"/>
      </geometry>
      <material name="white">
        <color rgba="1.0 1.0 1.0 1.0"/>
      </material>
    </visual>
  </link>
  <!-- Left Wheel -->
  <joint name="left_wheel_joint" type="continuous">
    <axis xyz="0 0 1"/>
    <parent link="base_link"/>
    <child link="left_wheel"/>
    <origin rpy="-1.5707963267948966 0 0" xyz="0 0.1 0.075"/>
  </joint>
  <link name="left_wheel">
    <visual>
      <geometry>
        <cylinder length="0.03" radius="0.0725"/>
      </geometry>
      <material name="gray">
        <color rgba="0.2 0.2 0.2 1"/>
      </material>
    </visual>
  </link>
  <!-- Right Wheel -->
  <joint name="right_wheel_joint" type="continuous">
    <axis xyz="0 0 1"/>
    <parent link="base_link"/>
    <child link="right_wheel"/>
    <origin rpy="-1.5707963267948966 0 0" xyz="0 -0.1 0.075"/>
  </joint>
  <link name="right_wheel">
    <visual>
      <geometry>
        <cylinder length="0.03" radius="0.0725"/>
      </geometry>
      <material name="gray">
        <color rgba="0.2 0.2 0.2 1"/>
      </material>
    </visual>
  </link>
</robot>
